2023-12-19 15:05:19,328:melissa.server.main:ERROR Server failed with msg All groups failed please make sure: 
- the path to the executable is correct, 
- the number of expected time steps is correct, 
- the simulation walltime was well estimated..
Traceback (most recent call last):
  File "/home/catzarakis/spack/opt/spack/linux-debian11-haswell/gcc-10.2.1/py-melissa-core-develop-v4kaesy527uxmla3ikqqafauc2e6lmou/lib/python3.10/site-packages/melissa/server/main.py", line 101, in main
    myserver.start()
  File "/home/catzarakis/spack/opt/spack/linux-debian11-haswell/gcc-10.2.1/py-melissa-core-develop-v4kaesy527uxmla3ikqqafauc2e6lmou/lib/python3.10/site-packages/melissa/server/sensitivity_analysis/sensitivity_analysis_server.py", line 202, in start
    self.server_online()
  File "/home/catzarakis/spack/opt/spack/linux-debian11-haswell/gcc-10.2.1/py-melissa-core-develop-v4kaesy527uxmla3ikqqafauc2e6lmou/lib/python3.10/site-packages/melissa/server/sensitivity_analysis/sensitivity_analysis_server.py", line 213, in server_online
    self.receive()
  File "/home/catzarakis/spack/opt/spack/linux-debian11-haswell/gcc-10.2.1/py-melissa-core-develop-v4kaesy527uxmla3ikqqafauc2e6lmou/lib/python3.10/site-packages/melissa/server/sensitivity_analysis/sensitivity_analysis_server.py", line 221, in receive
    status = self.run()
  File "/home/catzarakis/spack/opt/spack/linux-debian11-haswell/gcc-10.2.1/py-melissa-core-develop-v4kaesy527uxmla3ikqqafauc2e6lmou/lib/python3.10/site-packages/melissa/server/base_server.py", line 432, in run
    self.handle_fd()
  File "/home/catzarakis/spack/opt/spack/linux-debian11-haswell/gcc-10.2.1/py-melissa-core-develop-v4kaesy527uxmla3ikqqafauc2e6lmou/lib/python3.10/site-packages/melissa/server/base_server.py", line 475, in handle_fd
    new_grp = self.ft.handle_failed_group(group_id, group)
  File "/home/catzarakis/spack/opt/spack/linux-debian11-haswell/gcc-10.2.1/py-melissa-core-develop-v4kaesy527uxmla3ikqqafauc2e6lmou/lib/python3.10/site-packages/melissa/server/fault_tolerance.py", line 61, in handle_failed_group
    self.append_failed_id(group_id)
  File "/home/catzarakis/spack/opt/spack/linux-debian11-haswell/gcc-10.2.1/py-melissa-core-develop-v4kaesy527uxmla3ikqqafauc2e6lmou/lib/python3.10/site-packages/melissa/server/fault_tolerance.py", line 113, in append_failed_id
    raise Exception(
Exception: All groups failed please make sure: 
- the path to the executable is correct, 
- the number of expected time steps is correct, 
- the simulation walltime was well estimated.
2023-12-19 15:05:19,334:melissa.server.base_server:ERROR The server failed with an error
